<?xml version="1.0" ?>
<!-- =================================================================================== -->
<!-- |    This document was autogenerated by xacro from src/hexapod_description/robot/visual/hexapod.xacro | -->
<!-- |    EDITING THIS FILE BY HAND IS NOT RECOMMENDED                                 | -->
<!-- =================================================================================== -->
<robot name="hexapod">
  <!-- Specify some standard inertial calculations https://en.wikipedia.org/wiki/List_of_moments_of_inertia -->
  <!-- These make use of xacro's mathematical functionality -->
  <material name="white">
    <color rgba="0.894 0.914 0.929 1"/>
  </material>
  <material name="orange">
    <color rgba="0.969 0.878 0.6 1"/>
  </material>
  <material name="blue">
    <color rgba="0.898 0.918 0.929 1"/>
  </material>
  <material name="grey">
    <color rgba="0.502 0.502 0.502 1"/>
  </material>
  <material name="black">
    <color rgba="0 0 0 1"/>
  </material>
  <material name="red">
    <color rgba="1 0 0 1"/>
  </material>
  <material name="green">
    <color rgba="0 1 0 1"/>
  </material>
  <material name="yellow">
    <color rgba="1 1 0 1"/>
  </material>
  <ros2_control name="GazeboSimSystem" type="system">
    <hardware>
      <plugin>gz_ros2_control/GazeboSimSystem</plugin>
    </hardware>
    <!-- LEG 1 JOINTS -->
    <joint name="hip_joint_1">
      <command_interface name="effort">
        <param name="min">-100</param>
        <param name="max">100</param>
      </command_interface>
      <state_interface name="position">
        <param name="initial_value">0.0</param>
      </state_interface>
      <state_interface name="velocity"/>
      <state_interface name="effort"/>
    </joint>
    <joint name="knee_joint_1">
      <command_interface name="effort">
        <param name="min">-100</param>
        <param name="max">100</param>
      </command_interface>
      <state_interface name="position">
        <param name="initial_value">0.0</param>
      </state_interface>
      <state_interface name="velocity"/>
      <state_interface name="effort"/>
    </joint>
    <joint name="ankle_joint_1">
      <command_interface name="effort">
        <param name="min">-100</param>
        <param name="max">100</param>
      </command_interface>
      <state_interface name="position">
        <param name="initial_value">0.0</param>
      </state_interface>
      <state_interface name="velocity"/>
      <state_interface name="effort"/>
    </joint>
    <!-- LEG 2 JOINTS -->
    <joint name="hip_joint_2">
      <command_interface name="effort">
        <param name="min">-100</param>
        <param name="max">100</param>
      </command_interface>
      <state_interface name="position">
        <param name="initial_value">0.0</param>
      </state_interface>
      <state_interface name="velocity"/>
      <state_interface name="effort"/>
    </joint>
    <joint name="knee_joint_2">
      <command_interface name="effort">
        <param name="min">-100</param>
        <param name="max">100</param>
      </command_interface>
      <state_interface name="position">
        <param name="initial_value">0.0</param>
      </state_interface>
      <state_interface name="velocity"/>
      <state_interface name="effort"/>
    </joint>
    <joint name="ankle_joint_2">
      <command_interface name="effort">
        <param name="min">-100</param>
        <param name="max">100</param>
      </command_interface>
      <state_interface name="position">
        <param name="initial_value">0.0</param>
      </state_interface>
      <state_interface name="velocity"/>
      <state_interface name="effort"/>
    </joint>
    <!-- LEG 3 JOINTS -->
    <joint name="hip_joint_3">
      <command_interface name="effort">
        <param name="min">-100</param>
        <param name="max">100</param>
      </command_interface>
      <state_interface name="position">
        <param name="initial_value">0.0</param>
      </state_interface>
      <state_interface name="velocity"/>
      <state_interface name="effort"/>
    </joint>
    <joint name="knee_joint_3">
      <command_interface name="effort">
        <param name="min">-100</param>
        <param name="max">100</param>
      </command_interface>
      <state_interface name="position">
        <param name="initial_value">0.0</param>
      </state_interface>
      <state_interface name="velocity"/>
      <state_interface name="effort"/>
    </joint>
    <joint name="ankle_joint_3">
      <command_interface name="effort">
        <param name="min">-100</param>
        <param name="max">100</param>
      </command_interface>
      <state_interface name="position">
        <param name="initial_value">0.0</param>
      </state_interface>
      <state_interface name="velocity"/>
      <state_interface name="effort"/>
    </joint>
    <!-- LEG 4 JOINTS -->
    <joint name="hip_joint_4">
      <command_interface name="effort">
        <param name="min">-100</param>
        <param name="max">100</param>
      </command_interface>
      <state_interface name="position">
        <param name="initial_value">0.0</param>
      </state_interface>
      <state_interface name="velocity"/>
      <state_interface name="effort"/>
    </joint>
    <joint name="knee_joint_4">
      <command_interface name="effort">
        <param name="min">-100</param>
        <param name="max">100</param>
      </command_interface>
      <state_interface name="position">
        <param name="initial_value">0.0</param>
      </state_interface>
      <state_interface name="velocity"/>
      <state_interface name="effort"/>
    </joint>
    <joint name="ankle_joint_4">
      <command_interface name="effort">
        <param name="min">-100</param>
        <param name="max">100</param>
      </command_interface>
      <state_interface name="position">
        <param name="initial_value">0.0</param>
      </state_interface>
      <state_interface name="velocity"/>
      <state_interface name="effort"/>
    </joint>
    <!-- LEG 5 JOINTS -->
    <joint name="hip_joint_5">
      <command_interface name="effort">
        <param name="min">-100</param>
        <param name="max">100</param>
      </command_interface>
      <state_interface name="position">
        <param name="initial_value">0.0</param>
      </state_interface>
      <state_interface name="velocity"/>
      <state_interface name="effort"/>
    </joint>
    <joint name="knee_joint_5">
      <command_interface name="effort">
        <param name="min">-100</param>
        <param name="max">100</param>
      </command_interface>
      <state_interface name="position">
        <param name="initial_value">0.0</param>
      </state_interface>
      <state_interface name="velocity"/>
      <state_interface name="effort"/>
    </joint>
    <joint name="ankle_joint_5">
      <command_interface name="effort">
        <param name="min">-100</param>
        <param name="max">100</param>
      </command_interface>
      <state_interface name="position">
        <param name="initial_value">0.0</param>
      </state_interface>
      <state_interface name="velocity"/>
      <state_interface name="effort"/>
    </joint>
    <!-- LEG 6 JOINTS -->
    <joint name="hip_joint_6">
      <command_interface name="effort">
        <param name="min">-100</param>
        <param name="max">100</param>
      </command_interface>
      <state_interface name="position">
        <param name="initial_value">0.0</param>
      </state_interface>
      <state_interface name="velocity"/>
      <state_interface name="effort"/>
    </joint>
    <joint name="knee_joint_6">
      <command_interface name="effort">
        <param name="min">-100</param>
        <param name="max">100</param>
      </command_interface>
      <state_interface name="position">
        <param name="initial_value">0.0</param>
      </state_interface>
      <state_interface name="velocity"/>
      <state_interface name="effort"/>
    </joint>
    <joint name="ankle_joint_6">
      <command_interface name="effort">
        <param name="min">-100</param>
        <param name="max">100</param>
      </command_interface>
      <state_interface name="position">
        <param name="initial_value">0.0</param>
      </state_interface>
      <state_interface name="velocity"/>
      <state_interface name="effort"/>
    </joint>
  </ros2_control>
  <gazebo>
    <plugin filename="gz_ros2_control-system" name="gz_ros2_control::GazeboSimROS2ControlPlugin">
      <parameters>/home/oat/Desktop/FRA333_Kinematic_Project/install/hexapod_simulation/share/hexapod_simulation/config/controller_full.yaml</parameters>
    </plugin>
    <!-- Sensor Manager (for IMU, Lidar, etc.) -->
    <plugin filename="libignition-gazebo-sensors-system.so" name="ignition::gazebo::systems::Sensors">
      <render_engine>ogre2</render_engine>
    </plugin>
  </gazebo>
  <!-- Optional IMU sensor on base_link -->
  <!-- <gazebo reference="base_link">
    <sensor name="imu_sensor" type="imu">
      <always_on>true</always_on>
      <update_rate>100.0</update_rate>
      <visualize>true</visualize>
      <topic>/imu/data</topic>
      <gz_frame_id>base_link</gz_frame_id>
      <plugin filename="libignition-gazebo-imu-system.so"
              name="ignition::gazebo::systems::Imu"/>
      <pose>0 0 0 0 0 0</pose>
    </sensor>
  </gazebo> -->
  <!-- WORLD LINK (for fixing robot in air during tuning) -->
  <link name="world"/>
  <!-- FIXED JOINT (world to base_link - for PID tuning) -->
  <joint name="world_to_base" type="fixed">
    <parent link="world"/>
    <child link="base_link"/>
    <origin rpy="0 0 0" xyz="0 0 0.3"/>
  </joint>
  <!-- BASE LINK -->
  <link name="base_link">
    <inertial>
      <origin rpy="0 0 0" xyz="9.6259709536084E-06 -6.03599555802636E-06 -0.0030214605278231"/>
      <mass value="0.652718423695264"/>
      <inertia ixx="0.00164228924294238" ixy="-1.28564474462014E-09" ixz="8.22610664375957E-10" iyy="0.00164233674483393" iyz="-1.98002919852351E-10" izz="0.00328367106870498"/>
    </inertial>
    <visual>
      <origin rpy="0 0 0" xyz="0 0 0"/>
      <geometry>
        <mesh filename="package://hexapod_description/meshes/base_link.STL"/>
      </geometry>
      <material name="white"/>
    </visual>
    <collision>
      <origin rpy="0 0 0" xyz="0 0 0.002"/>
      <geometry>
        <cylinder length="0.064" radius="0.11"/>
      </geometry>
    </collision>
  </link>
  <!-- HIP LINK -->
  <link name="hip_link_1">
    <inertial>
      <origin rpy="0 0 0" xyz="0.0488185085747303 -0.00410063867439833 0.00163326248081042"/>
      <mass value="0.0882011859976947"/>
      <inertia ixx="9.38773089300775E-05" ixy="8.87632856357308E-06" ixz="2.7266876743089E-06" iyy="0.000124049448056631" iyz="-2.29027568962667E-07" izz="0.00012170057198104"/>
    </inertial>
    <visual>
      <origin rpy="0 0 0" xyz="0 0 0"/>
      <geometry>
        <mesh filename="package://hexapod_description/meshes/hip_link_1.STL"/>
      </geometry>
      <material name="orange"/>
    </visual>
    <collision>
      <origin rpy="0 0 0" xyz="0.0445 -0.0013 -0.0015"/>
      <geometry>
        <box size="0.126 0.061 0.077"/>
      </geometry>
    </collision>
  </link>
  <!-- HIP JOINT -->
  <joint name="hip_joint_1" type="revolute">
    <origin rpy="0 0 -1.5708" xyz="-1.2616E-05 -0.095255 0"/>
    <parent link="base_link"/>
    <child link="hip_link_1"/>
    <axis xyz="0 0 1"/>
    <limit effort="20.0" lower="-1.57" upper="1.57" velocity="5.0"/>
    <dynamics damping="0.019728" friction="0.01"/>
  </joint>
  <!-- KNEE LINK -->
  <link name="knee_link_1">
    <inertial>
      <origin rpy="0 0 0" xyz="-0.0475302249354476 -0.0303949843623502 -0.00382639103091394"/>
      <mass value="0.155431239013057"/>
      <inertia ixx="0.000125689460160167" ixy="-8.60189768522736E-05" ixz="-1.49872305256315E-06" iyy="0.000137645360683419" iyz="-1.51278826167929E-06" izz="0.000224456017656395"/>
    </inertial>
    <visual>
      <origin rpy="0 0 0" xyz="0 0 0"/>
      <geometry>
        <mesh filename="package://hexapod_description/meshes/knee_link_1.STL"/>
      </geometry>
      <material name="blue"/>
    </visual>
    <collision>
      <origin rpy="0 0 0" xyz="-0.0484 -0.0449 -0.0011"/>
      <geometry>
        <box size="0.134 0.129 0.080"/>
      </geometry>
    </collision>
  </link>
  <!-- KNEE JOINT -->
  <joint name="knee_joint_1" type="revolute">
    <origin rpy="1.5708 1.5708 3.142" xyz="0.078424 -0.0031746 0.0010006"/>
    <parent link="hip_link_1"/>
    <child link="knee_link_1"/>
    <axis xyz="0 0 1"/>
    <limit effort="20.0" lower="-3.14" upper="3.14" velocity="5.0"/>
    <dynamics damping="0.019728" friction="0.01"/>
  </joint>
  <!-- ANKLE LINK -->
  <link name="ankle_link_1">
    <inertial>
      <origin rpy="0 0 0" xyz="0.0767237006476303 -0.013659210334669 -0.00149577098480455"/>
      <mass value="0.31955999801834"/>
      <inertia ixx="0.000120289050869526" ixy="1.98010146951448E-05" ixz="-2.69503214059816E-06" iyy="0.000196681888150522" iyz="1.37145509688599E-06" izz="0.000177107331195337"/>
    </inertial>
    <visual>
      <origin rpy="0 0 0" xyz="0 0 0"/>
      <geometry>
        <mesh filename="package://hexapod_description/meshes/ankle_link_1.STL"/>
      </geometry>
      <material name="grey"/>
    </visual>
    <collision>
      <origin rpy="0 1.5708 0" xyz="0.0717 -0.0069 -0.0059"/>
      <geometry>
        <cylinder length="0.203" radius="0.038"/>
      </geometry>
    </collision>
  </link>
  <!-- ANKLE JOINT -->
  <joint name="ankle_joint_1" type="revolute">
    <origin rpy="0 0 0" xyz="-0.087752 -0.081834 0"/>
    <parent link="knee_link_1"/>
    <child link="ankle_link_1"/>
    <axis xyz="0 0 1"/>
    <limit effort="20.0" lower="-3.14" upper="3.14" velocity="5.0"/>
    <dynamics damping="0.019728" friction="0.01"/>
  </joint>
  <!-- FOOT POINTER LINK -->
  <link name="foot_pointer_1">
    <inertial>
      <origin rpy="0 0 0" xyz="-0.0049782363018493 0.000584199635433796 1.01521888723546E-05"/>
      <mass value="0.00634138756461707"/>
      <inertia ixx="3.1794072605368E-07" ixy="1.15940615410597E-08" ixz="2.00382787922864E-10" iyy="4.0938199625732E-07" iyz="-5.71299980008936E-11" izz="4.12726877457262E-07"/>
    </inertial>
    <visual>
      <origin rpy="0 0 0" xyz="0 0 0"/>
      <geometry>
        <mesh filename="package://hexapod_description/meshes/foot_pointer_1.STL"/>
      </geometry>
      <material name="grey"/>
    </visual>
    <collision>
      <origin rpy="0 0 0" xyz="-0.0081 0.0008 0"/>
      <geometry>
        <box size="0.032 0.023 0.022"/>
      </geometry>
    </collision>
  </link>
  <!-- FOOT POINTER JOINT -->
  <joint name="foot_pointer_joint_1" type="fixed">
    <origin rpy="0 0 0" xyz="0.18098 -0.022156 0"/>
    <parent link="ankle_link_1"/>
    <child link="foot_pointer_1"/>
  </joint>
  <!-- END EFFECTOR LINK -->
  <link name="end_effector_1">
    <inertial>
      <origin rpy="0 0 0" xyz="-0.0122067463278634 0.00152370640892938 6.47355637194841E-06"/>
      <mass value="0.00616673794613409"/>
      <inertia ixx="3.11902997781583E-07" ixy="1.22998576021055E-08" ixz="2.12679032607798E-10" iyy="4.0890866624375E-07" iyz="4.13472457938764E-11" izz="4.06602736445781E-07"/>
    </inertial>
    <visual>
      <origin rpy="0 0 0" xyz="0 0 0"/>
      <geometry>
        <mesh filename="package://hexapod_description/meshes/end_effector_1.STL"/>
      </geometry>
      <material name="grey"/>
    </visual>
    <collision>
      <origin rpy="0 0 0" xyz="-0.0157 0.0014 0"/>
      <geometry>
        <box size="0.032 0.022 0.022"/>
      </geometry>
    </collision>
  </link>
  <!-- END EFFECTOR JOINT -->
  <joint name="end_effector_joint_1" type="fixed">
    <origin rpy="0 0 0" xyz="0.0075528 -0.00094278 0"/>
    <parent link="foot_pointer_1"/>
    <child link="end_effector_1"/>
  </joint>
  <!-- FOOT CONTACT SPHERE -->
  <link name="foot_contact_1">
    <inertial>
      <origin rpy="0 0 0" xyz="0 0 0"/>
      <mass value="0.001"/>
      <inertia ixx="4e-08" ixy="0.0" ixz="0.0" iyy="4e-08" iyz="0.0" izz="4e-08"/>
    </inertial>
    <visual>
      <origin rpy="0 0 0" xyz="0 0 0"/>
      <geometry>
        <sphere radius="0.01"/>
      </geometry>
      <material name="black"/>
    </visual>
    <collision>
      <origin rpy="0 0 0" xyz="0 0 0"/>
      <geometry>
        <sphere radius="0.01"/>
      </geometry>
    </collision>
  </link>
  <!-- FOOT CONTACT JOINT -->
  <joint name="foot_contact_joint_1" type="fixed">
    <origin rpy="0 0 0" xyz="-0.012 0.0015 0"/>
    <parent link="end_effector_1"/>
    <child link="foot_contact_1"/>
  </joint>
  <!-- HIP LINK -->
  <link name="hip_link_2">
    <inertial>
      <origin rpy="0 0 0" xyz="0.0488185085747303 -0.00410063867439833 0.00163326248081042"/>
      <mass value="0.0882011859976947"/>
      <inertia ixx="9.38773089300775E-05" ixy="8.87632856357308E-06" ixz="2.7266876743089E-06" iyy="0.000124049448056631" iyz="-2.29027568962667E-07" izz="0.00012170057198104"/>
    </inertial>
    <visual>
      <origin rpy="0 0 0" xyz="0 0 0"/>
      <geometry>
        <mesh filename="package://hexapod_description/meshes/hip_link_1.STL"/>
      </geometry>
      <material name="orange"/>
    </visual>
    <collision>
      <origin rpy="0 0 0" xyz="0.0445 -0.0013 -0.0015"/>
      <geometry>
        <box size="0.126 0.061 0.077"/>
      </geometry>
    </collision>
  </link>
  <!-- HIP JOINT -->
  <joint name="hip_joint_2" type="revolute">
    <origin rpy="0 0 -0.5236" xyz="0.082487 -0.047638 0"/>
    <parent link="base_link"/>
    <child link="hip_link_2"/>
    <axis xyz="0 0 1"/>
    <limit effort="20.0" lower="-1.57" upper="1.57" velocity="5.0"/>
    <dynamics damping="0.019728" friction="0.01"/>
  </joint>
  <!-- KNEE LINK -->
  <link name="knee_link_2">
    <inertial>
      <origin rpy="0 0 0" xyz="-0.0475302249354476 -0.0303949843623502 -0.00382639103091394"/>
      <mass value="0.155431239013057"/>
      <inertia ixx="0.000125689460160167" ixy="-8.60189768522736E-05" ixz="-1.49872305256315E-06" iyy="0.000137645360683419" iyz="-1.51278826167929E-06" izz="0.000224456017656395"/>
    </inertial>
    <visual>
      <origin rpy="0 0 0" xyz="0 0 0"/>
      <geometry>
        <mesh filename="package://hexapod_description/meshes/knee_link_1.STL"/>
      </geometry>
      <material name="blue"/>
    </visual>
    <collision>
      <origin rpy="0 0 0" xyz="-0.0484 -0.0449 -0.0011"/>
      <geometry>
        <box size="0.134 0.129 0.080"/>
      </geometry>
    </collision>
  </link>
  <!-- KNEE JOINT -->
  <joint name="knee_joint_2" type="revolute">
    <origin rpy="1.5708 1.5708 3.142" xyz="0.078424 -0.0031746 0.0010006"/>
    <parent link="hip_link_2"/>
    <child link="knee_link_2"/>
    <axis xyz="0 0 1"/>
    <limit effort="20.0" lower="-3.14" upper="3.14" velocity="5.0"/>
    <dynamics damping="0.019728" friction="0.01"/>
  </joint>
  <!-- ANKLE LINK -->
  <link name="ankle_link_2">
    <inertial>
      <origin rpy="0 0 0" xyz="0.0767237006476303 -0.013659210334669 -0.00149577098480455"/>
      <mass value="0.31955999801834"/>
      <inertia ixx="0.000120289050869526" ixy="1.98010146951448E-05" ixz="-2.69503214059816E-06" iyy="0.000196681888150522" iyz="1.37145509688599E-06" izz="0.000177107331195337"/>
    </inertial>
    <visual>
      <origin rpy="0 0 0" xyz="0 0 0"/>
      <geometry>
        <mesh filename="package://hexapod_description/meshes/ankle_link_1.STL"/>
      </geometry>
      <material name="grey"/>
    </visual>
    <collision>
      <origin rpy="0 1.5708 0" xyz="0.0717 -0.0069 -0.0059"/>
      <geometry>
        <cylinder length="0.203" radius="0.038"/>
      </geometry>
    </collision>
  </link>
  <!-- ANKLE JOINT -->
  <joint name="ankle_joint_2" type="revolute">
    <origin rpy="0 0 0" xyz="-0.087752 -0.081834 0"/>
    <parent link="knee_link_2"/>
    <child link="ankle_link_2"/>
    <axis xyz="0 0 1"/>
    <limit effort="20.0" lower="-3.14" upper="3.14" velocity="5.0"/>
    <dynamics damping="0.019728" friction="0.01"/>
  </joint>
  <!-- FOOT POINTER LINK -->
  <link name="foot_pointer_2">
    <inertial>
      <origin rpy="0 0 0" xyz="-0.0049782363018493 0.000584199635433796 1.01521888723546E-05"/>
      <mass value="0.00634138756461707"/>
      <inertia ixx="3.1794072605368E-07" ixy="1.15940615410597E-08" ixz="2.00382787922864E-10" iyy="4.0938199625732E-07" iyz="-5.71299980008936E-11" izz="4.12726877457262E-07"/>
    </inertial>
    <visual>
      <origin rpy="0 0 0" xyz="0 0 0"/>
      <geometry>
        <mesh filename="package://hexapod_description/meshes/foot_pointer_1.STL"/>
      </geometry>
      <material name="grey"/>
    </visual>
    <collision>
      <origin rpy="0 0 0" xyz="-0.0081 0.0008 0"/>
      <geometry>
        <box size="0.032 0.023 0.022"/>
      </geometry>
    </collision>
  </link>
  <!-- FOOT POINTER JOINT -->
  <joint name="foot_pointer_joint_2" type="fixed">
    <origin rpy="0 0 0" xyz="0.18098 -0.022156 0"/>
    <parent link="ankle_link_2"/>
    <child link="foot_pointer_2"/>
  </joint>
  <!-- END EFFECTOR LINK -->
  <link name="end_effector_2">
    <inertial>
      <origin rpy="0 0 0" xyz="-0.0122067463278634 0.00152370640892938 6.47355637194841E-06"/>
      <mass value="0.00616673794613409"/>
      <inertia ixx="3.11902997781583E-07" ixy="1.22998576021055E-08" ixz="2.12679032607798E-10" iyy="4.0890866624375E-07" iyz="4.13472457938764E-11" izz="4.06602736445781E-07"/>
    </inertial>
    <visual>
      <origin rpy="0 0 0" xyz="0 0 0"/>
      <geometry>
        <mesh filename="package://hexapod_description/meshes/end_effector_1.STL"/>
      </geometry>
      <material name="grey"/>
    </visual>
    <collision>
      <origin rpy="0 0 0" xyz="-0.0157 0.0014 0"/>
      <geometry>
        <box size="0.032 0.022 0.022"/>
      </geometry>
    </collision>
  </link>
  <!-- END EFFECTOR JOINT -->
  <joint name="end_effector_joint_2" type="fixed">
    <origin rpy="0 0 0" xyz="0.0075528 -0.00094278 0"/>
    <parent link="foot_pointer_2"/>
    <child link="end_effector_2"/>
  </joint>
  <!-- FOOT CONTACT SPHERE -->
  <link name="foot_contact_2">
    <inertial>
      <origin rpy="0 0 0" xyz="0 0 0"/>
      <mass value="0.001"/>
      <inertia ixx="4e-08" ixy="0.0" ixz="0.0" iyy="4e-08" iyz="0.0" izz="4e-08"/>
    </inertial>
    <visual>
      <origin rpy="0 0 0" xyz="0 0 0"/>
      <geometry>
        <sphere radius="0.01"/>
      </geometry>
      <material name="black"/>
    </visual>
    <collision>
      <origin rpy="0 0 0" xyz="0 0 0"/>
      <geometry>
        <sphere radius="0.01"/>
      </geometry>
    </collision>
  </link>
  <!-- FOOT CONTACT JOINT -->
  <joint name="foot_contact_joint_2" type="fixed">
    <origin rpy="0 0 0" xyz="-0.012 0.0015 0"/>
    <parent link="end_effector_2"/>
    <child link="foot_contact_2"/>
  </joint>
  <!-- HIP LINK -->
  <link name="hip_link_3">
    <inertial>
      <origin rpy="0 0 0" xyz="0.0488185085747303 -0.00410063867439833 0.00163326248081042"/>
      <mass value="0.0882011859976947"/>
      <inertia ixx="9.38773089300775E-05" ixy="8.87632856357308E-06" ixz="2.7266876743089E-06" iyy="0.000124049448056631" iyz="-2.29027568962667E-07" izz="0.00012170057198104"/>
    </inertial>
    <visual>
      <origin rpy="0 0 0" xyz="0 0 0"/>
      <geometry>
        <mesh filename="package://hexapod_description/meshes/hip_link_1.STL"/>
      </geometry>
      <material name="orange"/>
    </visual>
    <collision>
      <origin rpy="0 0 0" xyz="0.0445 -0.0013 -0.0015"/>
      <geometry>
        <box size="0.126 0.061 0.077"/>
      </geometry>
    </collision>
  </link>
  <!-- HIP JOINT -->
  <joint name="hip_joint_3" type="revolute">
    <origin rpy="0 0 0.5236" xyz="0.082499 0.047616 0"/>
    <parent link="base_link"/>
    <child link="hip_link_3"/>
    <axis xyz="0 0 1"/>
    <limit effort="20.0" lower="-1.57" upper="1.57" velocity="5.0"/>
    <dynamics damping="0.019728" friction="0.01"/>
  </joint>
  <!-- KNEE LINK -->
  <link name="knee_link_3">
    <inertial>
      <origin rpy="0 0 0" xyz="-0.0475302249354476 -0.0303949843623502 -0.00382639103091394"/>
      <mass value="0.155431239013057"/>
      <inertia ixx="0.000125689460160167" ixy="-8.60189768522736E-05" ixz="-1.49872305256315E-06" iyy="0.000137645360683419" iyz="-1.51278826167929E-06" izz="0.000224456017656395"/>
    </inertial>
    <visual>
      <origin rpy="0 0 0" xyz="0 0 0"/>
      <geometry>
        <mesh filename="package://hexapod_description/meshes/knee_link_1.STL"/>
      </geometry>
      <material name="blue"/>
    </visual>
    <collision>
      <origin rpy="0 0 0" xyz="-0.0484 -0.0449 -0.0011"/>
      <geometry>
        <box size="0.134 0.129 0.080"/>
      </geometry>
    </collision>
  </link>
  <!-- KNEE JOINT -->
  <joint name="knee_joint_3" type="revolute">
    <origin rpy="1.5708 1.5708 3.142" xyz="0.078424 -0.0031746 0.0010006"/>
    <parent link="hip_link_3"/>
    <child link="knee_link_3"/>
    <axis xyz="0 0 1"/>
    <limit effort="20.0" lower="-3.14" upper="3.14" velocity="5.0"/>
    <dynamics damping="0.019728" friction="0.01"/>
  </joint>
  <!-- ANKLE LINK -->
  <link name="ankle_link_3">
    <inertial>
      <origin rpy="0 0 0" xyz="0.0767237006476303 -0.013659210334669 -0.00149577098480455"/>
      <mass value="0.31955999801834"/>
      <inertia ixx="0.000120289050869526" ixy="1.98010146951448E-05" ixz="-2.69503214059816E-06" iyy="0.000196681888150522" iyz="1.37145509688599E-06" izz="0.000177107331195337"/>
    </inertial>
    <visual>
      <origin rpy="0 0 0" xyz="0 0 0"/>
      <geometry>
        <mesh filename="package://hexapod_description/meshes/ankle_link_1.STL"/>
      </geometry>
      <material name="grey"/>
    </visual>
    <collision>
      <origin rpy="0 1.5708 0" xyz="0.0717 -0.0069 -0.0059"/>
      <geometry>
        <cylinder length="0.203" radius="0.038"/>
      </geometry>
    </collision>
  </link>
  <!-- ANKLE JOINT -->
  <joint name="ankle_joint_3" type="revolute">
    <origin rpy="0 0 0" xyz="-0.087752 -0.081834 0"/>
    <parent link="knee_link_3"/>
    <child link="ankle_link_3"/>
    <axis xyz="0 0 1"/>
    <limit effort="20.0" lower="-3.14" upper="3.14" velocity="5.0"/>
    <dynamics damping="0.019728" friction="0.01"/>
  </joint>
  <!-- FOOT POINTER LINK -->
  <link name="foot_pointer_3">
    <inertial>
      <origin rpy="0 0 0" xyz="-0.0049782363018493 0.000584199635433796 1.01521888723546E-05"/>
      <mass value="0.00634138756461707"/>
      <inertia ixx="3.1794072605368E-07" ixy="1.15940615410597E-08" ixz="2.00382787922864E-10" iyy="4.0938199625732E-07" iyz="-5.71299980008936E-11" izz="4.12726877457262E-07"/>
    </inertial>
    <visual>
      <origin rpy="0 0 0" xyz="0 0 0"/>
      <geometry>
        <mesh filename="package://hexapod_description/meshes/foot_pointer_1.STL"/>
      </geometry>
      <material name="grey"/>
    </visual>
    <collision>
      <origin rpy="0 0 0" xyz="-0.0081 0.0008 0"/>
      <geometry>
        <box size="0.032 0.023 0.022"/>
      </geometry>
    </collision>
  </link>
  <!-- FOOT POINTER JOINT -->
  <joint name="foot_pointer_joint_3" type="fixed">
    <origin rpy="0 0 0" xyz="0.18098 -0.022156 0"/>
    <parent link="ankle_link_3"/>
    <child link="foot_pointer_3"/>
  </joint>
  <!-- END EFFECTOR LINK -->
  <link name="end_effector_3">
    <inertial>
      <origin rpy="0 0 0" xyz="-0.0122067463278634 0.00152370640892938 6.47355637194841E-06"/>
      <mass value="0.00616673794613409"/>
      <inertia ixx="3.11902997781583E-07" ixy="1.22998576021055E-08" ixz="2.12679032607798E-10" iyy="4.0890866624375E-07" iyz="4.13472457938764E-11" izz="4.06602736445781E-07"/>
    </inertial>
    <visual>
      <origin rpy="0 0 0" xyz="0 0 0"/>
      <geometry>
        <mesh filename="package://hexapod_description/meshes/end_effector_1.STL"/>
      </geometry>
      <material name="grey"/>
    </visual>
    <collision>
      <origin rpy="0 0 0" xyz="-0.0157 0.0014 0"/>
      <geometry>
        <box size="0.032 0.022 0.022"/>
      </geometry>
    </collision>
  </link>
  <!-- END EFFECTOR JOINT -->
  <joint name="end_effector_joint_3" type="fixed">
    <origin rpy="0 0 0" xyz="0.0075528 -0.00094278 0"/>
    <parent link="foot_pointer_3"/>
    <child link="end_effector_3"/>
  </joint>
  <!-- FOOT CONTACT SPHERE -->
  <link name="foot_contact_3">
    <inertial>
      <origin rpy="0 0 0" xyz="0 0 0"/>
      <mass value="0.001"/>
      <inertia ixx="4e-08" ixy="0.0" ixz="0.0" iyy="4e-08" iyz="0.0" izz="4e-08"/>
    </inertial>
    <visual>
      <origin rpy="0 0 0" xyz="0 0 0"/>
      <geometry>
        <sphere radius="0.01"/>
      </geometry>
      <material name="black"/>
    </visual>
    <collision>
      <origin rpy="0 0 0" xyz="0 0 0"/>
      <geometry>
        <sphere radius="0.01"/>
      </geometry>
    </collision>
  </link>
  <!-- FOOT CONTACT JOINT -->
  <joint name="foot_contact_joint_3" type="fixed">
    <origin rpy="0 0 0" xyz="-0.012 0.0015 0"/>
    <parent link="end_effector_3"/>
    <child link="foot_contact_3"/>
  </joint>
  <!-- HIP LINK -->
  <link name="hip_link_4">
    <inertial>
      <origin rpy="0 0 0" xyz="0.0488185085747303 -0.00410063867439833 0.00163326248081042"/>
      <mass value="0.0882011859976947"/>
      <inertia ixx="9.38773089300775E-05" ixy="8.87632856357308E-06" ixz="2.7266876743089E-06" iyy="0.000124049448056631" iyz="-2.29027568962667E-07" izz="0.00012170057198104"/>
    </inertial>
    <visual>
      <origin rpy="0 0 0" xyz="0 0 0"/>
      <geometry>
        <mesh filename="package://hexapod_description/meshes/hip_link_1.STL"/>
      </geometry>
      <material name="orange"/>
    </visual>
    <collision>
      <origin rpy="0 0 0" xyz="0.0445 -0.0013 -0.0015"/>
      <geometry>
        <box size="0.126 0.061 0.077"/>
      </geometry>
    </collision>
  </link>
  <!-- HIP JOINT -->
  <joint name="hip_joint_4" type="revolute">
    <origin rpy="0 0 1.5708" xyz="1.2616E-05 0.095255 0"/>
    <parent link="base_link"/>
    <child link="hip_link_4"/>
    <axis xyz="0 0 1"/>
    <limit effort="20.0" lower="-1.57" upper="1.57" velocity="5.0"/>
    <dynamics damping="0.019728" friction="0.01"/>
  </joint>
  <!-- KNEE LINK -->
  <link name="knee_link_4">
    <inertial>
      <origin rpy="0 0 0" xyz="-0.0475302249354476 -0.0303949843623502 -0.00382639103091394"/>
      <mass value="0.155431239013057"/>
      <inertia ixx="0.000125689460160167" ixy="-8.60189768522736E-05" ixz="-1.49872305256315E-06" iyy="0.000137645360683419" iyz="-1.51278826167929E-06" izz="0.000224456017656395"/>
    </inertial>
    <visual>
      <origin rpy="0 0 0" xyz="0 0 0"/>
      <geometry>
        <mesh filename="package://hexapod_description/meshes/knee_link_1.STL"/>
      </geometry>
      <material name="blue"/>
    </visual>
    <collision>
      <origin rpy="0 0 0" xyz="-0.0484 -0.0449 -0.0011"/>
      <geometry>
        <box size="0.134 0.129 0.080"/>
      </geometry>
    </collision>
  </link>
  <!-- KNEE JOINT -->
  <joint name="knee_joint_4" type="revolute">
    <origin rpy="1.5708 1.5708 3.142" xyz="0.078424 -0.0031746 0.0010006"/>
    <parent link="hip_link_4"/>
    <child link="knee_link_4"/>
    <axis xyz="0 0 1"/>
    <limit effort="20.0" lower="-3.14" upper="3.14" velocity="5.0"/>
    <dynamics damping="0.019728" friction="0.01"/>
  </joint>
  <!-- ANKLE LINK -->
  <link name="ankle_link_4">
    <inertial>
      <origin rpy="0 0 0" xyz="0.0767237006476303 -0.013659210334669 -0.00149577098480455"/>
      <mass value="0.31955999801834"/>
      <inertia ixx="0.000120289050869526" ixy="1.98010146951448E-05" ixz="-2.69503214059816E-06" iyy="0.000196681888150522" iyz="1.37145509688599E-06" izz="0.000177107331195337"/>
    </inertial>
    <visual>
      <origin rpy="0 0 0" xyz="0 0 0"/>
      <geometry>
        <mesh filename="package://hexapod_description/meshes/ankle_link_1.STL"/>
      </geometry>
      <material name="grey"/>
    </visual>
    <collision>
      <origin rpy="0 1.5708 0" xyz="0.0717 -0.0069 -0.0059"/>
      <geometry>
        <cylinder length="0.203" radius="0.038"/>
      </geometry>
    </collision>
  </link>
  <!-- ANKLE JOINT -->
  <joint name="ankle_joint_4" type="revolute">
    <origin rpy="0 0 0" xyz="-0.087752 -0.081834 0"/>
    <parent link="knee_link_4"/>
    <child link="ankle_link_4"/>
    <axis xyz="0 0 1"/>
    <limit effort="20.0" lower="-3.14" upper="3.14" velocity="5.0"/>
    <dynamics damping="0.019728" friction="0.01"/>
  </joint>
  <!-- FOOT POINTER LINK -->
  <link name="foot_pointer_4">
    <inertial>
      <origin rpy="0 0 0" xyz="-0.0049782363018493 0.000584199635433796 1.01521888723546E-05"/>
      <mass value="0.00634138756461707"/>
      <inertia ixx="3.1794072605368E-07" ixy="1.15940615410597E-08" ixz="2.00382787922864E-10" iyy="4.0938199625732E-07" iyz="-5.71299980008936E-11" izz="4.12726877457262E-07"/>
    </inertial>
    <visual>
      <origin rpy="0 0 0" xyz="0 0 0"/>
      <geometry>
        <mesh filename="package://hexapod_description/meshes/foot_pointer_1.STL"/>
      </geometry>
      <material name="grey"/>
    </visual>
    <collision>
      <origin rpy="0 0 0" xyz="-0.0081 0.0008 0"/>
      <geometry>
        <box size="0.032 0.023 0.022"/>
      </geometry>
    </collision>
  </link>
  <!-- FOOT POINTER JOINT -->
  <joint name="foot_pointer_joint_4" type="fixed">
    <origin rpy="0 0 0" xyz="0.18098 -0.022156 0"/>
    <parent link="ankle_link_4"/>
    <child link="foot_pointer_4"/>
  </joint>
  <!-- END EFFECTOR LINK -->
  <link name="end_effector_4">
    <inertial>
      <origin rpy="0 0 0" xyz="-0.0122067463278634 0.00152370640892938 6.47355637194841E-06"/>
      <mass value="0.00616673794613409"/>
      <inertia ixx="3.11902997781583E-07" ixy="1.22998576021055E-08" ixz="2.12679032607798E-10" iyy="4.0890866624375E-07" iyz="4.13472457938764E-11" izz="4.06602736445781E-07"/>
    </inertial>
    <visual>
      <origin rpy="0 0 0" xyz="0 0 0"/>
      <geometry>
        <mesh filename="package://hexapod_description/meshes/end_effector_1.STL"/>
      </geometry>
      <material name="grey"/>
    </visual>
    <collision>
      <origin rpy="0 0 0" xyz="-0.0157 0.0014 0"/>
      <geometry>
        <box size="0.032 0.022 0.022"/>
      </geometry>
    </collision>
  </link>
  <!-- END EFFECTOR JOINT -->
  <joint name="end_effector_joint_4" type="fixed">
    <origin rpy="0 0 0" xyz="0.0075528 -0.00094278 0"/>
    <parent link="foot_pointer_4"/>
    <child link="end_effector_4"/>
  </joint>
  <!-- FOOT CONTACT SPHERE -->
  <link name="foot_contact_4">
    <inertial>
      <origin rpy="0 0 0" xyz="0 0 0"/>
      <mass value="0.001"/>
      <inertia ixx="4e-08" ixy="0.0" ixz="0.0" iyy="4e-08" iyz="0.0" izz="4e-08"/>
    </inertial>
    <visual>
      <origin rpy="0 0 0" xyz="0 0 0"/>
      <geometry>
        <sphere radius="0.01"/>
      </geometry>
      <material name="black"/>
    </visual>
    <collision>
      <origin rpy="0 0 0" xyz="0 0 0"/>
      <geometry>
        <sphere radius="0.01"/>
      </geometry>
    </collision>
  </link>
  <!-- FOOT CONTACT JOINT -->
  <joint name="foot_contact_joint_4" type="fixed">
    <origin rpy="0 0 0" xyz="-0.012 0.0015 0"/>
    <parent link="end_effector_4"/>
    <child link="foot_contact_4"/>
  </joint>
  <!-- HIP LINK -->
  <link name="hip_link_5">
    <inertial>
      <origin rpy="0 0 0" xyz="0.0488185085747303 -0.00410063867439833 0.00163326248081042"/>
      <mass value="0.0882011859976947"/>
      <inertia ixx="9.38773089300775E-05" ixy="8.87632856357308E-06" ixz="2.7266876743089E-06" iyy="0.000124049448056631" iyz="-2.29027568962667E-07" izz="0.00012170057198104"/>
    </inertial>
    <visual>
      <origin rpy="0 0 0" xyz="0 0 0"/>
      <geometry>
        <mesh filename="package://hexapod_description/meshes/hip_link_1.STL"/>
      </geometry>
      <material name="orange"/>
    </visual>
    <collision>
      <origin rpy="0 0 0" xyz="0.0445 -0.0013 -0.0015"/>
      <geometry>
        <box size="0.126 0.061 0.077"/>
      </geometry>
    </collision>
  </link>
  <!-- HIP JOINT -->
  <joint name="hip_joint_5" type="revolute">
    <origin rpy="0 0 2.618" xyz="-0.082487 0.047638 0"/>
    <parent link="base_link"/>
    <child link="hip_link_5"/>
    <axis xyz="0 0 1"/>
    <limit effort="20.0" lower="-1.57" upper="1.57" velocity="5.0"/>
    <dynamics damping="0.019728" friction="0.01"/>
  </joint>
  <!-- KNEE LINK -->
  <link name="knee_link_5">
    <inertial>
      <origin rpy="0 0 0" xyz="-0.0475302249354476 -0.0303949843623502 -0.00382639103091394"/>
      <mass value="0.155431239013057"/>
      <inertia ixx="0.000125689460160167" ixy="-8.60189768522736E-05" ixz="-1.49872305256315E-06" iyy="0.000137645360683419" iyz="-1.51278826167929E-06" izz="0.000224456017656395"/>
    </inertial>
    <visual>
      <origin rpy="0 0 0" xyz="0 0 0"/>
      <geometry>
        <mesh filename="package://hexapod_description/meshes/knee_link_1.STL"/>
      </geometry>
      <material name="blue"/>
    </visual>
    <collision>
      <origin rpy="0 0 0" xyz="-0.0484 -0.0449 -0.0011"/>
      <geometry>
        <box size="0.134 0.129 0.080"/>
      </geometry>
    </collision>
  </link>
  <!-- KNEE JOINT -->
  <joint name="knee_joint_5" type="revolute">
    <origin rpy="1.5708 1.5708 3.142" xyz="0.078424 -0.0031746 0.0010006"/>
    <parent link="hip_link_5"/>
    <child link="knee_link_5"/>
    <axis xyz="0 0 1"/>
    <limit effort="20.0" lower="-3.14" upper="3.14" velocity="5.0"/>
    <dynamics damping="0.019728" friction="0.01"/>
  </joint>
  <!-- ANKLE LINK -->
  <link name="ankle_link_5">
    <inertial>
      <origin rpy="0 0 0" xyz="0.0767237006476303 -0.013659210334669 -0.00149577098480455"/>
      <mass value="0.31955999801834"/>
      <inertia ixx="0.000120289050869526" ixy="1.98010146951448E-05" ixz="-2.69503214059816E-06" iyy="0.000196681888150522" iyz="1.37145509688599E-06" izz="0.000177107331195337"/>
    </inertial>
    <visual>
      <origin rpy="0 0 0" xyz="0 0 0"/>
      <geometry>
        <mesh filename="package://hexapod_description/meshes/ankle_link_1.STL"/>
      </geometry>
      <material name="grey"/>
    </visual>
    <collision>
      <origin rpy="0 1.5708 0" xyz="0.0717 -0.0069 -0.0059"/>
      <geometry>
        <cylinder length="0.203" radius="0.038"/>
      </geometry>
    </collision>
  </link>
  <!-- ANKLE JOINT -->
  <joint name="ankle_joint_5" type="revolute">
    <origin rpy="0 0 0" xyz="-0.087752 -0.081834 0"/>
    <parent link="knee_link_5"/>
    <child link="ankle_link_5"/>
    <axis xyz="0 0 1"/>
    <limit effort="20.0" lower="-3.14" upper="3.14" velocity="5.0"/>
    <dynamics damping="0.019728" friction="0.01"/>
  </joint>
  <!-- FOOT POINTER LINK -->
  <link name="foot_pointer_5">
    <inertial>
      <origin rpy="0 0 0" xyz="-0.0049782363018493 0.000584199635433796 1.01521888723546E-05"/>
      <mass value="0.00634138756461707"/>
      <inertia ixx="3.1794072605368E-07" ixy="1.15940615410597E-08" ixz="2.00382787922864E-10" iyy="4.0938199625732E-07" iyz="-5.71299980008936E-11" izz="4.12726877457262E-07"/>
    </inertial>
    <visual>
      <origin rpy="0 0 0" xyz="0 0 0"/>
      <geometry>
        <mesh filename="package://hexapod_description/meshes/foot_pointer_1.STL"/>
      </geometry>
      <material name="grey"/>
    </visual>
    <collision>
      <origin rpy="0 0 0" xyz="-0.0081 0.0008 0"/>
      <geometry>
        <box size="0.032 0.023 0.022"/>
      </geometry>
    </collision>
  </link>
  <!-- FOOT POINTER JOINT -->
  <joint name="foot_pointer_joint_5" type="fixed">
    <origin rpy="0 0 0" xyz="0.18098 -0.022156 0"/>
    <parent link="ankle_link_5"/>
    <child link="foot_pointer_5"/>
  </joint>
  <!-- END EFFECTOR LINK -->
  <link name="end_effector_5">
    <inertial>
      <origin rpy="0 0 0" xyz="-0.0122067463278634 0.00152370640892938 6.47355637194841E-06"/>
      <mass value="0.00616673794613409"/>
      <inertia ixx="3.11902997781583E-07" ixy="1.22998576021055E-08" ixz="2.12679032607798E-10" iyy="4.0890866624375E-07" iyz="4.13472457938764E-11" izz="4.06602736445781E-07"/>
    </inertial>
    <visual>
      <origin rpy="0 0 0" xyz="0 0 0"/>
      <geometry>
        <mesh filename="package://hexapod_description/meshes/end_effector_1.STL"/>
      </geometry>
      <material name="grey"/>
    </visual>
    <collision>
      <origin rpy="0 0 0" xyz="-0.0157 0.0014 0"/>
      <geometry>
        <box size="0.032 0.022 0.022"/>
      </geometry>
    </collision>
  </link>
  <!-- END EFFECTOR JOINT -->
  <joint name="end_effector_joint_5" type="fixed">
    <origin rpy="0 0 0" xyz="0.0075528 -0.00094278 0"/>
    <parent link="foot_pointer_5"/>
    <child link="end_effector_5"/>
  </joint>
  <!-- FOOT CONTACT SPHERE -->
  <link name="foot_contact_5">
    <inertial>
      <origin rpy="0 0 0" xyz="0 0 0"/>
      <mass value="0.001"/>
      <inertia ixx="4e-08" ixy="0.0" ixz="0.0" iyy="4e-08" iyz="0.0" izz="4e-08"/>
    </inertial>
    <visual>
      <origin rpy="0 0 0" xyz="0 0 0"/>
      <geometry>
        <sphere radius="0.01"/>
      </geometry>
      <material name="black"/>
    </visual>
    <collision>
      <origin rpy="0 0 0" xyz="0 0 0"/>
      <geometry>
        <sphere radius="0.01"/>
      </geometry>
    </collision>
  </link>
  <!-- FOOT CONTACT JOINT -->
  <joint name="foot_contact_joint_5" type="fixed">
    <origin rpy="0 0 0" xyz="-0.012 0.0015 0"/>
    <parent link="end_effector_5"/>
    <child link="foot_contact_5"/>
  </joint>
  <!-- HIP LINK -->
  <link name="hip_link_6">
    <inertial>
      <origin rpy="0 0 0" xyz="0.0488185085747303 -0.00410063867439833 0.00163326248081042"/>
      <mass value="0.0882011859976947"/>
      <inertia ixx="9.38773089300775E-05" ixy="8.87632856357308E-06" ixz="2.7266876743089E-06" iyy="0.000124049448056631" iyz="-2.29027568962667E-07" izz="0.00012170057198104"/>
    </inertial>
    <visual>
      <origin rpy="0 0 0" xyz="0 0 0"/>
      <geometry>
        <mesh filename="package://hexapod_description/meshes/hip_link_1.STL"/>
      </geometry>
      <material name="orange"/>
    </visual>
    <collision>
      <origin rpy="0 0 0" xyz="0.0445 -0.0013 -0.0015"/>
      <geometry>
        <box size="0.126 0.061 0.077"/>
      </geometry>
    </collision>
  </link>
  <!-- HIP JOINT -->
  <joint name="hip_joint_6" type="revolute">
    <origin rpy="0 0 -2.618" xyz="-0.082499 -0.047616 0"/>
    <parent link="base_link"/>
    <child link="hip_link_6"/>
    <axis xyz="0 0 1"/>
    <limit effort="20.0" lower="-1.57" upper="1.57" velocity="5.0"/>
    <dynamics damping="0.019728" friction="0.01"/>
  </joint>
  <!-- KNEE LINK -->
  <link name="knee_link_6">
    <inertial>
      <origin rpy="0 0 0" xyz="-0.0475302249354476 -0.0303949843623502 -0.00382639103091394"/>
      <mass value="0.155431239013057"/>
      <inertia ixx="0.000125689460160167" ixy="-8.60189768522736E-05" ixz="-1.49872305256315E-06" iyy="0.000137645360683419" iyz="-1.51278826167929E-06" izz="0.000224456017656395"/>
    </inertial>
    <visual>
      <origin rpy="0 0 0" xyz="0 0 0"/>
      <geometry>
        <mesh filename="package://hexapod_description/meshes/knee_link_1.STL"/>
      </geometry>
      <material name="blue"/>
    </visual>
    <collision>
      <origin rpy="0 0 0" xyz="-0.0484 -0.0449 -0.0011"/>
      <geometry>
        <box size="0.134 0.129 0.080"/>
      </geometry>
    </collision>
  </link>
  <!-- KNEE JOINT -->
  <joint name="knee_joint_6" type="revolute">
    <origin rpy="1.5708 1.5708 3.142" xyz="0.078424 -0.0031746 0.0010006"/>
    <parent link="hip_link_6"/>
    <child link="knee_link_6"/>
    <axis xyz="0 0 1"/>
    <limit effort="20.0" lower="-3.14" upper="3.14" velocity="5.0"/>
    <dynamics damping="0.019728" friction="0.01"/>
  </joint>
  <!-- ANKLE LINK -->
  <link name="ankle_link_6">
    <inertial>
      <origin rpy="0 0 0" xyz="0.0767237006476303 -0.013659210334669 -0.00149577098480455"/>
      <mass value="0.31955999801834"/>
      <inertia ixx="0.000120289050869526" ixy="1.98010146951448E-05" ixz="-2.69503214059816E-06" iyy="0.000196681888150522" iyz="1.37145509688599E-06" izz="0.000177107331195337"/>
    </inertial>
    <visual>
      <origin rpy="0 0 0" xyz="0 0 0"/>
      <geometry>
        <mesh filename="package://hexapod_description/meshes/ankle_link_1.STL"/>
      </geometry>
      <material name="grey"/>
    </visual>
    <collision>
      <origin rpy="0 1.5708 0" xyz="0.0717 -0.0069 -0.0059"/>
      <geometry>
        <cylinder length="0.203" radius="0.038"/>
      </geometry>
    </collision>
  </link>
  <!-- ANKLE JOINT -->
  <joint name="ankle_joint_6" type="revolute">
    <origin rpy="0 0 0" xyz="-0.087752 -0.081834 0"/>
    <parent link="knee_link_6"/>
    <child link="ankle_link_6"/>
    <axis xyz="0 0 1"/>
    <limit effort="20.0" lower="-3.14" upper="3.14" velocity="5.0"/>
    <dynamics damping="0.019728" friction="0.01"/>
  </joint>
  <!-- FOOT POINTER LINK -->
  <link name="foot_pointer_6">
    <inertial>
      <origin rpy="0 0 0" xyz="-0.0049782363018493 0.000584199635433796 1.01521888723546E-05"/>
      <mass value="0.00634138756461707"/>
      <inertia ixx="3.1794072605368E-07" ixy="1.15940615410597E-08" ixz="2.00382787922864E-10" iyy="4.0938199625732E-07" iyz="-5.71299980008936E-11" izz="4.12726877457262E-07"/>
    </inertial>
    <visual>
      <origin rpy="0 0 0" xyz="0 0 0"/>
      <geometry>
        <mesh filename="package://hexapod_description/meshes/foot_pointer_1.STL"/>
      </geometry>
      <material name="grey"/>
    </visual>
    <collision>
      <origin rpy="0 0 0" xyz="-0.0081 0.0008 0"/>
      <geometry>
        <box size="0.032 0.023 0.022"/>
      </geometry>
    </collision>
  </link>
  <!-- FOOT POINTER JOINT -->
  <joint name="foot_pointer_joint_6" type="fixed">
    <origin rpy="0 0 0" xyz="0.18098 -0.022156 0"/>
    <parent link="ankle_link_6"/>
    <child link="foot_pointer_6"/>
  </joint>
  <!-- END EFFECTOR LINK -->
  <link name="end_effector_6">
    <inertial>
      <origin rpy="0 0 0" xyz="-0.0122067463278634 0.00152370640892938 6.47355637194841E-06"/>
      <mass value="0.00616673794613409"/>
      <inertia ixx="3.11902997781583E-07" ixy="1.22998576021055E-08" ixz="2.12679032607798E-10" iyy="4.0890866624375E-07" iyz="4.13472457938764E-11" izz="4.06602736445781E-07"/>
    </inertial>
    <visual>
      <origin rpy="0 0 0" xyz="0 0 0"/>
      <geometry>
        <mesh filename="package://hexapod_description/meshes/end_effector_1.STL"/>
      </geometry>
      <material name="grey"/>
    </visual>
    <collision>
      <origin rpy="0 0 0" xyz="-0.0157 0.0014 0"/>
      <geometry>
        <box size="0.032 0.022 0.022"/>
      </geometry>
    </collision>
  </link>
  <!-- END EFFECTOR JOINT -->
  <joint name="end_effector_joint_6" type="fixed">
    <origin rpy="0 0 0" xyz="0.0075528 -0.00094278 0"/>
    <parent link="foot_pointer_6"/>
    <child link="end_effector_6"/>
  </joint>
  <!-- FOOT CONTACT SPHERE -->
  <link name="foot_contact_6">
    <inertial>
      <origin rpy="0 0 0" xyz="0 0 0"/>
      <mass value="0.001"/>
      <inertia ixx="4e-08" ixy="0.0" ixz="0.0" iyy="4e-08" iyz="0.0" izz="4e-08"/>
    </inertial>
    <visual>
      <origin rpy="0 0 0" xyz="0 0 0"/>
      <geometry>
        <sphere radius="0.01"/>
      </geometry>
      <material name="black"/>
    </visual>
    <collision>
      <origin rpy="0 0 0" xyz="0 0 0"/>
      <geometry>
        <sphere radius="0.01"/>
      </geometry>
    </collision>
  </link>
  <!-- FOOT CONTACT JOINT -->
  <joint name="foot_contact_joint_6" type="fixed">
    <origin rpy="0 0 0" xyz="-0.012 0.0015 0"/>
    <parent link="end_effector_6"/>
    <child link="foot_contact_6"/>
  </joint>
</robot>
